Traceback (most recent call last):
  File "C:\Users\jacob\.conda\envs\jupyterbook\lib\site-packages\jupyter_cache\executors\utils.py", line 58, in single_nb_execution
    executenb(
  File "C:\Users\jacob\.conda\envs\jupyterbook\lib\site-packages\nbclient\client.py", line 1305, in execute
    return NotebookClient(nb=nb, resources=resources, km=km, **kwargs).execute()
  File "C:\Users\jacob\.conda\envs\jupyterbook\lib\site-packages\jupyter_core\utils\__init__.py", line 166, in wrapped
    return loop.run_until_complete(inner)
  File "C:\Users\jacob\.conda\envs\jupyterbook\lib\asyncio\base_events.py", line 647, in run_until_complete
    return future.result()
  File "C:\Users\jacob\.conda\envs\jupyterbook\lib\site-packages\nbclient\client.py", line 705, in async_execute
    await self.async_execute_cell(
  File "C:\Users\jacob\.conda\envs\jupyterbook\lib\site-packages\nbclient\client.py", line 1058, in async_execute_cell
    await self._check_raise_for_error(cell, cell_index, exec_reply)
  File "C:\Users\jacob\.conda\envs\jupyterbook\lib\site-packages\nbclient\client.py", line 914, in _check_raise_for_error
    raise CellExecutionError.from_cell_and_msg(cell, exec_reply_content)
nbclient.exceptions.CellExecutionError: An error occurred while executing the following cell:
------------------
#iso_code to name
import country_converter as coco
import math
hotel_data_first = hotel_data[0:1000]
print(len(hotel_data))

# count = 0
# for i, row in hotel_data_first.iterrows():
#     print(hotel_data.loc[i].at['country'])
#     if i[13] != 'country' and not type(i[13]) == float:
#         name = coco.convert(i[13], to='name_short')
#         print('test')
#         print(hotel_data_first.loc[i].at['country'])
#         # hotel_data_first.loc[i].at['country']=name

#     count += 1

# for i, row in hotel_data.iterrows():
#     if not type(row[13]) == float:
#         name = coco.convert(row[13], to='name_short')
#         hotel_data.loc[i].at['country']=name

# print(hotel_data.head())
#standard_names = coco.convert(names=some_names, to='name_short')
------------------


[1;31m---------------------------------------------------------------------------[0m
[1;31mModuleNotFoundError[0m                       Traceback (most recent call last)
Cell [1;32mIn[3], line 2[0m
[0;32m      1[0m [38;5;66;03m#iso_code to name[39;00m
[1;32m----> 2[0m [38;5;28;01mimport[39;00m [38;5;21;01mcountry_converter[39;00m [38;5;28;01mas[39;00m [38;5;21;01mcoco[39;00m
[0;32m      3[0m [38;5;28;01mimport[39;00m [38;5;21;01mmath[39;00m
[0;32m      4[0m hotel_data_first [38;5;241m=[39m hotel_data[[38;5;241m0[39m:[38;5;241m1000[39m]

[1;31mModuleNotFoundError[0m: No module named 'country_converter'

