Traceback (most recent call last):
  File "C:\Users\jacob\.conda\envs\jupyterbook\lib\site-packages\jupyter_cache\executors\utils.py", line 58, in single_nb_execution
    executenb(
  File "C:\Users\jacob\.conda\envs\jupyterbook\lib\site-packages\nbclient\client.py", line 1305, in execute
    return NotebookClient(nb=nb, resources=resources, km=km, **kwargs).execute()
  File "C:\Users\jacob\.conda\envs\jupyterbook\lib\site-packages\jupyter_core\utils\__init__.py", line 166, in wrapped
    return loop.run_until_complete(inner)
  File "C:\Users\jacob\.conda\envs\jupyterbook\lib\asyncio\base_events.py", line 647, in run_until_complete
    return future.result()
  File "C:\Users\jacob\.conda\envs\jupyterbook\lib\site-packages\nbclient\client.py", line 705, in async_execute
    await self.async_execute_cell(
  File "C:\Users\jacob\.conda\envs\jupyterbook\lib\site-packages\nbclient\client.py", line 1058, in async_execute_cell
    await self._check_raise_for_error(cell, cell_index, exec_reply)
  File "C:\Users\jacob\.conda\envs\jupyterbook\lib\site-packages\nbclient\client.py", line 914, in _check_raise_for_error
    raise CellExecutionError.from_cell_and_msg(cell, exec_reply_content)
nbclient.exceptions.CellExecutionError: An error occurred while executing the following cell:
------------------
hotel_data = pd.read_table("hotel_booking.csv", delimiter=";")
print(hotel_data.head())
------------------


[1;31m---------------------------------------------------------------------------[0m
[1;31mNameError[0m                                 Traceback (most recent call last)
Cell [1;32mIn[1], line 1[0m
[1;32m----> 1[0m hotel_data [38;5;241m=[39m [43mpd[49m[38;5;241m.[39mread_table([38;5;124m"[39m[38;5;124mhotel_booking.csv[39m[38;5;124m"[39m, delimiter[38;5;241m=[39m[38;5;124m"[39m[38;5;124m;[39m[38;5;124m"[39m)
[0;32m      2[0m [38;5;28mprint[39m(hotel_data[38;5;241m.[39mhead())

[1;31mNameError[0m: name 'pd' is not defined

